Workbook

Sheet Introduction
B2: Workbook Overview: Excel_Demo.xlsx
B4: This workbook contains 12 worksheets covering various business operations, from sales and payroll to inventory and client management. Here's a detailed breakdown:
B6: 📋 Worksheet Summary
B8: # | C8: Sheet Name | D8: Rows × Cols | E8: Key Columns | F8: Purpose
B9: 1 | C9: Formula | D9: 17 × 13 | E9: OrderID, CustomerName, Email, Product, Category, Price, Quantity | F9: Order management with lookup areas (J-M columns) for practicing formulas like VLOOKUP/XLOOKUP
B10: 2 | C10: Email_Data | D10: 41 × 6 | E10: Client_ID, Client_Name, Email, Course, Fee_Status, Enrollment_Date | F10: Client enrollment tracking; useful for generating payment reminders and follow-up emails
B11: 3 | C11: Raw_Messy_Data | D11: 45 × 3 | E11: Name, City, Sales | F11: Data cleaning practice—contains inconsistent spacing, case variations, and duplicates
B12: 4 | C12: Payroll_Data | D12: 41 × 6 | E12: Emp_ID, Employee_Name, Department, Basic_Salary, Bonus, Deductions | F12: Payroll processing and net salary calculations
B13: 5 | C13: Bank_Books | D13: 41 × 3 | E13: Date, Description, Amount | F13: Internal accounting records for bank reconciliation
B14: 6 | C14: Bank_Statement | D14: 41 × 3 | E14: Date, Description, Amount | F14: External bank statement data for reconciliation comparison
B15: 7 | C15: Expenses | D15: 41 × 4 | E15: Date, Category, Description, Amount | F15: Expense tracking by category (Travel, Marketing, Office, Software, Utilities)
B16: 8 | C16: Inventory | D16: 41 × 5 | E16: Item_ID, Item_Name, Stock_Available, Reorder_Level, Supplier | F16: Inventory management and low-stock alerts
B17: 9 | C17: Client_Followup | D17: 41 × 5 | E17: Client_Name, Company, Last_Contact_Date, Status, Next_Followup | F17: CRM/sales pipeline tracking with follow-up scheduling
B18: 10 | C18: Budget_vs_Actual | D18: 7 × 3 | E18: Department, Budget, Actual | F18: Budget variance analysis by department
B19: 11 | C19: Sales_Data | D19: 401 × 4 | E19: Date, Region, Product, Sales_Amount | F19: Large sales dataset for pivot tables, dashboards, and trend analysis
B20: 12 | C20: Prompts | D20: 35 × 3 | E20: Sheet Name, Topic/Demo, Claude Prompt | F20: Reference sheet with sample prompts and use cases
B22: 🎯 Use Cases by Worksheet
B24: Worksheet | C24: What You Can Do
B25: Formula | C25: Practice lookup formulas (VLOOKUP, XLOOKUP, INDEX-MATCH)
B26: Email_Data | C26: Generate personalized reminder emails for pending payments
B27: Raw_Messy_Data | C27: Clean data: trim spaces, standardize text, remove duplicates
B28: Payroll_Data | C28: Calculate net salaries, create department summaries
B29: Bank_Books + Bank_Statement | C29: Perform bank reconciliation, identify unmatched transactions
B30: Expenses | C30: Analyze spending by category, create monthly expense reports
B31: Inventory | C31: Identify low-stock items, generate reorder alerts
B32: Client_Followup | C32: Track sales pipeline, identify upcoming follow-ups
B33: Budget_vs_Actual | C33: Variance analysis, identify over/under-budget departments
B34: Sales_Data | C34: Create dashboards, pivot tables, regional/product analysis
B36: 💡 Quick Insights
B38: Largest dataset: Sales_Data with 400 transactions across 4 regions and 4 products
B39: Data quality issues: Raw_Messy_Data needs cleaning (spacing, capitalization, duplicates)
B40: Reconciliation pair: Bank_Books and Bank_Statement are designed for comparison exercises
B41: Ready-to-use prompts: The Prompts sheet contains 20+ sample tasks you can try
B43: Would you like me to perform any specific analysis or task on any of these worksheets?

Sheet Index
A1: 📑 Workbook Index - Navigation Guide
A2: # | B2: Worksheet Name | C2: Description | D2: Quick Navigate (Ctrl+G)
A3: 1 | B3: Formula | C3: Order management & lookup practice | D3: =HYPERLINK("#Formula!A1","Formula") -> Formula | F3: =_xlfn.FORMULATEXT(D3) -> =HYPERLINK("#Formula!A1","Formula")
A4: 2 | B4: Email_Data | C4: Client enrollment & payment tracking | D4: =HYPERLINK("#Email_Data!A1","Email_Data") -> Email_Data | F4: =_xlfn.FORMULATEXT(D4) -> =HYPERLINK("#Email_Data!A1","Email_Data")
A5: 3 | B5: Raw_Messy_Data | C5: Data cleaning practice | D5: =HYPERLINK("#Raw_Messy_Data!A1","Raw_Messy_Data") -> Raw_Messy_Data | F5: =_xlfn.FORMULATEXT(D5) -> =HYPERLINK("#Raw_Messy_Data!A1","Raw_Messy_Data")
A6: 4 | B6: Payroll_Data | C6: Employee salary calculations | D6: =HYPERLINK("#Payroll_Data!A1","Payroll_Data") -> Payroll_Data | F6: =_xlfn.FORMULATEXT(D6) -> =HYPERLINK("#Payroll_Data!A1","Payroll_Data")
A7: 5 | B7: Bank_Books | C7: Internal accounting records | D7: =HYPERLINK("#Bank_Books!A1","Bank_Books") -> Bank_Books | F7: =_xlfn.FORMULATEXT(D7) -> =HYPERLINK("#Bank_Books!A1","Bank_Books")
A8: 6 | B8: Bank_Statement | C8: External bank data | D8: =HYPERLINK("#Bank_Statement!A1","Bank_Statement") -> Bank_Statement | F8: =_xlfn.FORMULATEXT(D8) -> =HYPERLINK("#Bank_Statement!A1","Bank_Statement")
A9: 7 | B9: Expenses | C9: Expense tracking by category | D9: =HYPERLINK("#Expenses!A1","Expenses") -> Expenses | F9: =_xlfn.FORMULATEXT(D9) -> =HYPERLINK("#Expenses!A1","Expenses")
A10: 8 | B10: Inventory | C10: Stock management & alerts | D10: =HYPERLINK("#Inventory!A1","Inventory") -> Inventory | F10: =_xlfn.FORMULATEXT(D10) -> =HYPERLINK("#Inventory!A1","Inventory")
A11: 9 | B11: Client_Followup | C11: CRM & sales pipeline | D11: =HYPERLINK("#Client_Followup!A1","Client_Followup") -> Client_Followup | F11: =_xlfn.FORMULATEXT(D11) -> =HYPERLINK("#Client_Followup!A1","Client_Followup")
A12: 10 | B12: Budget_vs_Actual | C12: Budget variance analysis | D12: =HYPERLINK("#Budget_vs_Actual!A1","Budget_vs_Actual") -> Budget_vs_Actual | F12: =_xlfn.FORMULATEXT(D12) -> =HYPERLINK("#Budget_vs_Actual!A1","Budget_vs_Actual")
A13: 11 | B13: Sales_Data | C13: Large sales dataset for analysis | D13: =HYPERLINK("#Sales_Data!A1","Sales_Data") -> Sales_Data | F13: =_xlfn.FORMULATEXT(D13) -> =HYPERLINK("#Sales_Data!A1","Sales_Data")
A14: 12 | B14: Prompts | C14: Sample prompts & use cases | D14: =HYPERLINK("#Prompts!A1","Prompts") -> Prompts | F14: =_xlfn.FORMULATEXT(D14) -> =HYPERLINK("#Prompts!A1","Prompts")
A16: 📌 How to Navigate:
A17: 1️⃣ Click any sheet tab at the bottom of Excel
A18: 2️⃣ Or press Ctrl+G, paste a value from column D, and press Enter
A19: 3️⃣ Or use keyboard: Ctrl+Page Down / Ctrl+Page Up to move between sheets

Sheet Formula
A1: OrderID | B1: CustomerName | C1: Email | D1: Product | E1: Category | F1: Price | G1: Quantity | J1: OrderID | K1: CustomerName | L1: Quantity | M1: Price
A2: ORD10000 | B2: Pooja Bansal | C2: pooja95@gmail.com | D2: Charger | E2: Tech | F2: 78572.14 | G2: 4 | J2: ORD10000 | K2: =_xlfn.XLOOKUP(J2,$A$2:$A$17,$B$2:$B$17,"Not Found") -> Pooja Bansal | L2: =_xlfn.XLOOKUP(J2,$A$2:$A$17,$G$2:$G$17,"") -> 4 | M2: =_xlfn.XLOOKUP(J2,$A$2:$A$17,$F$2:$F$17,"") -> 78572.14
A3: ORD10001 | B3: Sneha Verma | C3: sneha12@gmail.com | D3: Tablet | E3: Electronics | F3: 43393.19 | G3: 3 | J3: ORD10002 | K3: =_xlfn.XLOOKUP(J3,$A$2:$A$17,$B$2:$B$17,"Not Found") -> Arjun Singh | L3: =_xlfn.XLOOKUP(J3,$A$2:$A$17,$G$2:$G$17,"") -> 2 | M3: =_xlfn.XLOOKUP(J3,$A$2:$A$17,$F$2:$F$17,"") -> 38208.78
A4: ORD10002 | B4: Arjun Singh | C4: arjun5@gmail.com | D4: Headphones | E4: Electronics | F4: 38208.78 | G4: 2 | J4: ORD10004 | K4: =_xlfn.XLOOKUP(J4,$A$2:$A$17,$B$2:$B$17,"Not Found") -> Neha Gupta | L4: =_xlfn.XLOOKUP(J4,$A$2:$A$17,$G$2:$G$17,"") -> 3 | M4: =_xlfn.XLOOKUP(J4,$A$2:$A$17,$F$2:$F$17,"") -> 73256.56
A5: ORD10003 | B5: Neha Singh | C5: neha3@gmail.com | D5: Headphones | E5: Electronics | F5: 44514.23 | G5: 5 | J5: ORD10006 | K5: =_xlfn.XLOOKUP(J5,$A$2:$A$17,$B$2:$B$17,"Not Found") -> Rohit Arora | L5: =_xlfn.XLOOKUP(J5,$A$2:$A$17,$G$2:$G$17,"") -> 1 | M5: =_xlfn.XLOOKUP(J5,$A$2:$A$17,$F$2:$F$17,"") -> 64501.86
A6: ORD10004 | B6: Neha Gupta | C6: neha60@gmail.com | D6: Mouse | E6: Electronics | F6: 73256.56 | G6: 3 | J6: ORD10008 | K6: =_xlfn.XLOOKUP(J6,$A$2:$A$17,$B$2:$B$17,"Not Found") -> Not Found | L6: =_xlfn.XLOOKUP(J6,$A$2:$A$17,$G$2:$G$17,"") | M6: =_xlfn.XLOOKUP(J6,$A$2:$A$17,$F$2:$F$17,"")
A7: ORD10005 | B7: Meena Sharma | C7: meena84@gmail.com | D7: USB Cable | E7: Tech | F7: 67063.78 | G7: 3 | J7: ORD10010 | K7: =_xlfn.XLOOKUP(J7,$A$2:$A$17,$B$2:$B$17,"Not Found") -> Neha Kapoor | L7: =_xlfn.XLOOKUP(J7,$A$2:$A$17,$G$2:$G$17,"") -> 1 | M7: =_xlfn.XLOOKUP(J7,$A$2:$A$17,$F$2:$F$17,"") -> 69761.1
A8: ORD10006 | B8: Rohit Arora | C8: rohit138@gmail.com | D8: Monitor | E8: Electronics | F8: 64501.86 | G8: 1 | J8: ORD10012 | K8: =_xlfn.XLOOKUP(J8,$A$2:$A$17,$B$2:$B$17,"Not Found") -> Arjun Sharma | L8: =_xlfn.XLOOKUP(J8,$A$2:$A$17,$G$2:$G$17,"") -> 5 | M8: =_xlfn.XLOOKUP(J8,$A$2:$A$17,$F$2:$F$17,"") -> 31399.6
A9: ORD10007 | B9: Sneha Verma | C9: sneha180@gmail.com | D9: Monitor | E9: Gadgets | F9: 61418.64 | G9: 1 | J9: ORD10014 | K9: =_xlfn.XLOOKUP(J9,$A$2:$A$17,$B$2:$B$17,"Not Found") -> Anjali Mehta | L9: =_xlfn.XLOOKUP(J9,$A$2:$A$17,$G$2:$G$17,"") -> 2 | M9: =_xlfn.XLOOKUP(J9,$A$2:$A$17,$F$2:$F$17,"") -> 32961.2
A10: ORD10009 | B10: Vikas Gupta | C10: vikas143@gmail.com | D10: Mouse | E10: Gadgets | F10: 5379.97 | G10: 2 | J10: ORD10016 | K10: =_xlfn.XLOOKUP(J10,$A$2:$A$17,$B$2:$B$17,"Not Found") -> Anjali Jain | L10: =_xlfn.XLOOKUP(J10,$A$2:$A$17,$G$2:$G$17,"") -> 4 | M10: =_xlfn.XLOOKUP(J10,$A$2:$A$17,$F$2:$F$17,"") -> 32137.43
A11: ORD10010 | B11: Neha Kapoor | C11: neha49@gmail.com | D11: Charger | E11: Electronics | F11: 69761.1 | G11: 1
A12: ORD10012 | B12: Arjun Sharma | C12: arjun46@gmail.com | D12: USB Cable | E12: Electronics | F12: 31399.6 | G12: 5
A13: ORD10013 | B13: Rohit Jain | C13: rohit42@gmail.com | D13: Tablet | E13: Tech | F13: 18167.94 | G13: 2
A14: ORD10014 | B14: Anjali Mehta | C14: anjali175@gmail.com | D14: Webcam | E14: Electronics | F14: 32961.2 | G14: 2
A15: ORD10015 | B15: Priya Arora | C15: priya199@gmail.com | D15: Webcam | E15: Gadgets | F15: 46556.77 | G15: 4
A16: ORD10016 | B16: Anjali Jain | C16: anjali106@gmail.com | D16: Headphones | E16: Electronics | F16: 32137.43 | G16: 4
A17: ORD10017 | B17: Karan Singh | C17: karan171@gmail.com | D17: Mouse | E17: Electronics | F17: 10041.37 | G17: 1

Sheet Email_Data
A1: Client_ID | B1: Client_Name | C1: Email | D1: Course | E1: Fee_Status | F1: Enrollment_Date | G1: Email_Subject | H1: Email_Body | I1: Followup_Email
A2: 101 | B2: Nikhil Gupta | C2: user1@email.com | D2: Power BI | E2: Pending | F2: 46024 | G2: =IF(E2="Pending","Payment Reminder - "&D2&" Course Fee Due",IF(E2="Paid","Payment Confirmation - "&D2&" Course Fee Received","")) -> Payment Reminder - Power BI Course Fee Due | H2: =IF(E2="Pending","Dear "&B2&","&CHAR(10)&CHAR(10)&"This is a friendly reminder that your fee for the "&D2&" course enrolled on "&TEXT(F2,"YYYY-MM-DD")&" is still pending."&CHAR(10)&CHAR(10)&"Please complete your payment at your earliest convenience to continue uninterrupted access to course materials."&CHAR(10)&CHAR(10)&"If you have already made the payment, please disregard this message."&CHAR(10)&CHAR(10)&"Best regards,"&CHAR(10)&"Training Team",IF(E2="Paid","Dear "&B2&","&CHAR(10)&CHAR(10)&"Thank you for your payment! We are pleased to confirm that your fee for the "&D2&" course enrolled on "&TEXT(F2,"YYYY-MM-DD")&" has been successfully received."&CHAR(10)&CHAR(10)&"You now have full access to all course materials and resources."&CHAR(10)&CHAR(10)&"We wish you the best in your learning journey!"&CHAR(10)&CHAR(10)&"Best regards,"&CHAR(10)&"Training Team","")) -> Dear Nikhil Gupta, This is a friendly reminder that your fee for the Power BI course enrolled on 2026-01-02 is still pending. Please complete your payment at your earliest convenience to continue uninterrupted access to course materials. If you have already made the payment, please disregard this message. Best regards, Training Team | I2: =IF(D2="Advanced Excel","Dear "&B2&", We hope you're enjoying your Advanced Excel course that you enrolled in on "&TEXT(F2,"YYYY-MM-DD")&_xlfn._LONGTEXT(". We wanted to check in on your progress and see if you have any questions about the course material. Our team is here to support your learning journey! Here are some resources you might find helpful: • Access our Excel formula library • Join our weekly"," live Q&A sessions • Download practice worksheets Feel free to reach out if you need any assistance. Best regards, Training Team"),"")
A3: 102 | B3: Arjun Sharma | C3: user2@email.com | D3: GST Mastery | E3: Pending | F3: 46025 | G3: =IF(E3="Pending","Payment Reminder - "&D3&" Course Fee Due",IF(E3="Paid","Payment Confirmation - "&D3&" Course Fee Received","")) -> Payment Reminder - GST Mastery Course Fee Due | H3: =IF(E3="Pending","Dear "&B3&","&CHAR(10)&CHAR(10)&"This is a friendly reminder that your fee for the "&D3&" course enrolled on "&TEXT(F3,"YYYY-MM-DD")&" is still pending."&CHAR(10)&CHAR(10)&"Please complete your payment at your earliest convenience to continue uninterrupted access to course materials."&CHAR(10)&CHAR(10)&"If you have already made the payment, please disregard this message."&CHAR(10)&CHAR(10)&"Best regards,"&CHAR(10)&"Training Team",IF(E3="Paid","Dear "&B3&","&CHAR(10)&CHAR(10)&"Thank you for your payment! We are pleased to confirm that your fee for the "&D3&" course enrolled on "&TEXT(F3,"YYYY-MM-DD")&" has been successfully received."&CHAR(10)&CHAR(10)&"You now have full access to all course materials and resources."&CHAR(10)&CHAR(10)&"We wish you the best in your learning journey!"&CHAR(10)&CHAR(10)&"Best regards,"&CHAR(10)&"Training Team","")) -> Dear Arjun Sharma, This is a friendly reminder that your fee for the GST Mastery course enrolled on 2026-01-03 is still pending. Please complete your payment at your earliest convenience to continue uninterrupted access to course materials. If you have already made the payment, please disregard this message. Best regards, Training Team | I3: =IF(D3="Advanced Excel","Dear "&B3&", We hope you're enjoying your Advanced Excel course that you enrolled in on "&TEXT(F3,"YYYY-MM-DD")&_xlfn._LONGTEXT(". We wanted to check in on your progress and see if you have any questions about the course material. Our team is here to support your learning journey! Here are some resources you might find helpful: • Access our Excel formula library • Join our weekly"," live Q&A sessions • Download practice worksheets Feel free to reach out if you need any assistance. Best regards, Training Team"),"")
A4: 103 | B4: Deepak Verma | C4: user3@email.com | D4: Tally Prime | E4: Pending | F4: 46026 | G4: =IF(E4="Pending","Payment Reminder - "&D4&" Course Fee Due",IF(E4="Paid","Payment Confirmation - "&D4&" Course Fee Received","")) -> Payment Reminder - Tally Prime Course Fee Due | H4: =IF(E4="Pending","Dear "&B4&","&CHAR(10)&CHAR(10)&"This is a friendly reminder that your fee for the "&D4&" course enrolled on "&TEXT(F4,"YYYY-MM-DD")&" is still pending."&CHAR(10)&CHAR(10)&"Please complete your payment at your earliest convenience to continue uninterrupted access to course materials."&CHAR(10)&CHAR(10)&"If you have already made the payment, please disregard this message."&CHAR(10)&CHAR(10)&"Best regards,"&CHAR(10)&"Training Team",IF(E4="Paid","Dear "&B4&","&CHAR(10)&CHAR(10)&"Thank you for your payment! We are pleased to confirm that your fee for the "&D4&" course enrolled on "&TEXT(F4,"YYYY-MM-DD")&" has been successfully received."&CHAR(10)&CHAR(10)&"You now have full access to all course materials and resources."&CHAR(10)&CHAR(10)&"We wish you the best in your learning journey!"&CHAR(10)&CHAR(10)&"Best regards,"&CHAR(10)&"Training Team","")) -> Dear Deepak Verma, This is a friendly reminder that your fee for the Tally Prime course enrolled on 2026-01-04 is still pending. Please complete your payment at your earliest convenience to continue uninterrupted access to course materials. If you have already made the payment, please disregard this message. Best regards, Training Team | I4: =IF(D4="Advanced Excel","Dear "&B4&", We hope you're enjoying your Advanced Excel course that you enrolled in on "&TEXT(F4,"YYYY-MM-DD")&_xlfn._LONGTEXT(". We wanted to check in on your progress and see if you have any questions about the course material. Our team is here to support your learning journey! Here are some resources you might find helpful: • Access our Excel formula library • Join our weekly"," live Q&A sessions • Download practice worksheets Feel free to reach out if you need any assistance. Best regards, Training Team"),"")
A5: 104 | B5: Rahul Gupta | C5: user4@email.com | D5: Power BI | E5: Pending | F5: 46027 | G5: =IF(E5="Pending","Payment Reminder - "&D5&" Course Fee Due",IF(E5="Paid","Payment Confirmation - "&D5&" Course Fee Received","")) -> Payment Reminder - Power BI Course Fee Due | H5: =IF(E5="Pending","Dear "&B5&","&CHAR(10)&CHAR(10)&"This is a friendly reminder that your fee for the "&D5&" course enrolled on "&TEXT(F5,"YYYY-MM-DD")&" is still pending."&CHAR(10)&CHAR(10)&"Please complete your payment at your earliest convenience to continue uninterrupted access to course materials."&CHAR(10)&CHAR(10)&"If you have already made the payment, please disregard this message."&CHAR(10)&CHAR(10)&"Best regards,"&CHAR(10)&"Training Team",IF(E5="Paid","Dear "&B5&","&CHAR(10)&CHAR(10)&"Thank you for your payment! We are pleased to confirm that your fee for the "&D5&" course enrolled on "&TEXT(F5,"YYYY-MM-DD")&" has been successfully received."&CHAR(10)&CHAR(10)&"You now have full access to all course materials and resources."&CHAR(10)&CHAR(10)&"We wish you the best in your learning journey!"&CHAR(10)&CHAR(10)&"Best regards,"&CHAR(10)&"Training Team","")) -> Dear Rahul Gupta, This is a friendly reminder that your fee for the Power BI course enrolled on 2026-01-05 is still pending. Please complete your payment at your earliest convenience to continue uninterrupted access to course materials. If you have already made the payment, please disregard this message. Best regards, Training Team | I5: =IF(D5="Advanced Excel","Dear "&B5&", We hope you're enjoying your Advanced Excel course that you enrolled in on "&TEXT(F5,"YYYY-MM-DD")&_xlfn._LONGTEXT(". We wanted to check in on your progress and see if you have any questions about the course material. Our team is here to support your learning journey! Here are some resources you might find helpful: • Access our Excel formula library • Join our weekly"," live Q&A sessions • Download practice worksheets Feel free to reach out if you need any assistance. Best regards, Training Team"),"")
A6: 105 | B6: Neha Singh | C6: user5@email.com | D6: Advanced Excel | E6: Pending | F6: 46028 | G6: =IF(E6="Pending","Payment Reminder - "&D6&" Course Fee Due",IF(E6="Paid","Payment Confirmation - "&D6&" Course Fee Received","")) -> Payment Reminder - Advanced Excel Course Fee Due | H6: =IF(E6="Pending","Dear "&B6&","&CHAR(10)&CHAR(10)&"This is a friendly reminder that your fee for the "&D6&" course enrolled on "&TEXT(F6,"YYYY-MM-DD")&" is still pending."&CHAR(10)&CHAR(10)&"Please complete your payment at your earliest convenience to continue uninterrupted access to course materials."&CHAR(10)&CHAR(10)&"If you have already made the payment, please disregard this message."&CHAR(10)&CHAR(10)&"Best regards,"&CHAR(10)&"Training Team",IF(E6="Paid","Dear "&B6&","&CHAR(10)&CHAR(10)&"Thank you for your payment! We are pleased to confirm that your fee for the "&D6&" course enrolled on "&TEXT(F6,"YYYY-MM-DD")&" has been successfully received."&CHAR(10)&CHAR(10)&"You now have full access to all course materials and resources."&CHAR(10)&CHAR(10)&"We wish you the best in your learning journey!"&CHAR(10)&CHAR(10)&"Best regards,"&CHAR(10)&"Training Team","")) -> Dear Neha Singh, This is a friendly reminder that your fee for the Advanced Excel course enrolled on 2026-01-06 is still pending. Please complete your payment at your earliest convenience to continue uninterrupted access to course materials. If you have already made the payment, please disregard this message. Best regards, Training Team | I6: =IF(D6="Advanced Excel","Dear "&B6&", We hope you're enjoying your Advanced Excel course that you enrolled in on "&TEXT(F6,"YYYY-MM-DD")&_xlfn._LONGTEXT(". We wanted to check in on your progress and see if you have any questions about the course material. Our team is here to support your learning journey! Here are some resources you might find helpful: • Access our Excel formula library • Join our weekly"," live Q&A sessions • Download practice worksheets Feel free to reach out if you need any assistance. Best regards, Training Team"),"") -> Dear Neha Singh, We hope you're enjoying your Advanced Excel course that you enrolled in on 2026-01-06. We wanted to check in on your progress and see if you have any questions about the course material. Our team is here to support your learning journey! Here are some resources you might find helpful: • Access our Excel formula library • Join our weekly live Q&A sessions • Download practice worksheets Feel free to reach out if you need any assistance. Best regards, Training Team
A7: 106 | B7: Deepak Gupta | C7: user6@email.com | D7: Tally Prime | E7: Paid | F7: 46029 | G7: =IF(E7="Pending","Payment Reminder - "&D7&" Course Fee Due",IF(E7="Paid","Payment Confirmation - "&D7&" Course Fee Received","")) -> Payment Confirmation - Tally Prime Course Fee Received | H7: =IF(E7="Pending","Dear "&B7&","&CHAR(10)&CHAR(10)&"This is a friendly reminder that your fee for the "&D7&" course enrolled on "&TEXT(F7,"YYYY-MM-DD")&" is still pending."&CHAR(10)&CHAR(10)&"Please complete your payment at your earliest convenience to continue uninterrupted access to course materials."&CHAR(10)&CHAR(10)&"If you have already made the payment, please disregard this message."&CHAR(10)&CHAR(10)&"Best regards,"&CHAR(10)&"Training Team",IF(E7="Paid","Dear "&B7&","&CHAR(10)&CHAR(10)&"Thank you for your payment! We are pleased to confirm that your fee for the "&D7&" course enrolled on "&TEXT(F7,"YYYY-MM-DD")&" has been successfully received."&CHAR(10)&CHAR(10)&"You now have full access to all course materials and resources."&CHAR(10)&CHAR(10)&"We wish you the best in your learning journey!"&CHAR(10)&CHAR(10)&"Best regards,"&CHAR(10)&"Training Team","")) -> Dear Deepak Gupta, Thank you for your payment! We are pleased to confirm that your fee for the Tally Prime course enrolled on 2026-01-07 has been successfully received. You now have full access to all course materials and resources. We wish you the best in your learning journey! Best regards, Training Team | I7: =IF(D7="Advanced Excel","Dear "&B7&", We hope you're enjoying your Advanced Excel course that you enrolled in on "&TEXT(F7,"YYYY-MM-DD")&_xlfn._LONGTEXT(". We wanted to check in on your progress and see if you have any questions about the course material. Our team is here to support your learning journey! Here are some resources you might find helpful: • Access our Excel formula library • Join our weekly"," live Q&A sessions • Download practice worksheets Feel free to reach out if you need any assistance. Best regards, Training Team"),"")
A8: 107 | B8: Vikas Singh | C8: user7@email.com | D8: Power BI | E8: Paid | F8: 46030 | G8: =IF(E8="Pending","Payment Reminder - "&D8&" Course Fee Due",IF(E8="Paid","Payment Confirmation - "&D8&" Course Fee Received","")) -> Payment Confirmation - Power BI Course Fee Received | H8: =IF(E8="Pending","Dear "&B8&","&CHAR(10)&CHAR(10)&"This is a friendly reminder that your fee for the "&D8&" course enrolled on "&TEXT(F8,"YYYY-MM-DD")&" is still pending."&CHAR(10)&CHAR(10)&"Please complete your payment at your earliest convenience to continue uninterrupted access to course materials."&CHAR(10)&CHAR(10)&"If you have already made the payment, please disregard this message."&CHAR(10)&CHAR(10)&"Best regards,"&CHAR(10)&"Training Team",IF(E8="Paid","Dear "&B8&","&CHAR(10)&CHAR(10)&"Thank you for your payment! We are pleased to confirm that your fee for the "&D8&" course enrolled on "&TEXT(F8,"YYYY-MM-DD")&" has been successfully received."&CHAR(10)&CHAR(10)&"You now have full access to all course materials and resources."&CHAR(10)&CHAR(10)&"We wish you the best in your learning journey!"&CHAR(10)&CHAR(10)&"Best regards,"&CHAR(10)&"Training Team","")) -> Dear Vikas Singh, Thank you for your payment! We are pleased to confirm that your fee for the Power BI course enrolled on 2026-01-08 has been successfully received. You now have full access to all course materials and resources. We wish you the best in your learning journey! Best regards, Training Team | I8: =IF(D8="Advanced Excel","Dear "&B8&", We hope you're enjoying your Advanced Excel course that you enrolled in on "&TEXT(F8,"YYYY-MM-DD")&_xlfn._LONGTEXT(". We wanted to check in on your progress and see if you have any questions about the course material. Our team is here to support your learning journey! Here are some resources you might find helpful: • Access our Excel formula library • Join our weekly"," live Q&A sessions • Download practice worksheets Feel free to reach out if you need any assistance. Best regards, Training Team"),"")
A9: 108 | B9: Aman Gupta | C9: user8@email.com | D9: Tally Prime | E9: Pending | F9: 46031 | G9: =IF(E9="Pending","Payment Reminder - "&D9&" Course Fee Due",IF(E9="Paid","Payment Confirmation - "&D9&" Course Fee Received","")) -> Payment Reminder - Tally Prime Course Fee Due | H9: =IF(E9="Pending","Dear "&B9&","&CHAR(10)&CHAR(10)&"This is a friendly reminder that your fee for the "&D9&" course enrolled on "&TEXT(F9,"YYYY-MM-DD")&" is still pending."&CHAR(10)&CHAR(10)&"Please complete your payment at your earliest convenience to continue uninterrupted access to course materials."&CHAR(10)&CHAR(10)&"If you have already made the payment, please disregard this message."&CHAR(10)&CHAR(10)&"Best regards,"&CHAR(10)&"Training Team",IF(E9="Paid","Dear "&B9&","&CHAR(10)&CHAR(10)&"Thank you for your payment! We are pleased to confirm that your fee for the "&D9&" course enrolled on "&TEXT(F9,"YYYY-MM-DD")&" has been successfully received."&CHAR(10)&CHAR(10)&"You now have full access to all course materials and resources."&CHAR(10)&CHAR(10)&"We wish you the best in your learning journey!"&CHAR(10)&CHAR(10)&"Best regards,"&CHAR(10)&"Training Team","")) -> Dear Aman Gupta, This is a friendly reminder that your fee for the Tally Prime course enrolled on 2026-01-09 is still pending. Please complete your payment at your earliest convenience to continue uninterrupted access to course materials. If you have already made the payment, please disregard this message. Best regards, Training Team | I9: =IF(D9="Advanced Excel","Dear "&B9&", We hope you're enjoying your Advanced Excel course that you enrolled in on "&TEXT(F9,"YYYY-MM-DD")&_xlfn._LONGTEXT(". We wanted to check in on your progress and see if you have any questions about the course material. Our team is here to support your learning journey! Here are some resources you might find helpful: • Access our Excel formula library • Join our weekly"," live Q&A sessions • Download practice worksheets Feel free to reach out if you need any assistance. Best regards, Training Team"),"")
A10: 109 | B10: Karan Gupta | C10: user9@email.com | D10: GST Mastery | E10: Pending | F10: 46032 | G10: =IF(E10="Pending","Payment Reminder - "&D10&" Course Fee Due",IF(E10="Paid","Payment Confirmation - "&D10&" Course Fee Received","")) -> Payment Reminder - GST Mastery Course Fee Due | H10: =IF(E10="Pending","Dear "&B10&","&CHAR(10)&CHAR(10)&"This is a friendly reminder that your fee for the "&D10&" course enrolled on "&TEXT(F10,"YYYY-MM-DD")&" is still pending."&CHAR(10)&CHAR(10)&"Please complete your payment at your earliest convenience to continue uninterrupted access to course materials."&CHAR(10)&CHAR(10)&"If you have already made the payment, please disregard this message."&CHAR(10)&CHAR(10)&"Best regards,"&CHAR(10)&"Training Team",IF(E10="Paid","Dear "&B10&","&CHAR(10)&CHAR(10)&"Thank you for your payment! We are pleased to confirm that your fee for the "&D10&" course enrolled on "&TEXT(F10,"YYYY-MM-DD")&" has been successfully received."&CHAR(10)&CHAR(10)&"You now have full access to all course materials and resources."&CHAR(10)&CHAR(10)&"We wish you the best in your learning journey!"&CHAR(10)&CHAR(10)&"Best regards,"&CHAR(10)&"Training Team","")) -> Dear Karan Gupta, This is a friendly reminder that your fee for the GST Mastery course enrolled on 2026-01-10 is still pending. Please complete your payment at your earliest convenience to continue uninterrupted access to course materials. If you have already made the payment, please disregard this message. Best regards, Training Team | I10: =IF(D10="Advanced Excel","Dear "&B10&", We hope you're enjoying your Advanced Excel course that you enrolled in on "&TEXT(F10,"YYYY-MM-DD")&_xlfn._LONGTEXT(". We wanted to check in on your progress and see if you have any questions about the course material. Our team is here to support your learning journey! Here are some resources you might find helpful: • Access our Excel formula library • Join our weekly"," live Q&A sessions • Download practice worksheets Feel free to reach out if you need any assistance. Best regards, Training Team"),"")
A11: 110 | B11: Karan Verma | C11: user10@email.com | D11: Advanced Excel | E11: Pending | F11: 46033 | G11: =IF(E11="Pending","Payment Reminder - "&D11&" Course Fee Due",IF(E11="Paid","Payment Confirmation - "&D11&" Course Fee Received","")) -> Payment Reminder - Advanced Excel Course Fee Due | H11: =IF(E11="Pending","Dear "&B11&","&CHAR(10)&CHAR(10)&"This is a friendly reminder that your fee for the "&D11&" course enrolled on "&TEXT(F11,"YYYY-MM-DD")&" is still pending."&CHAR(10)&CHAR(10)&"Please complete your payment at your earliest convenience to continue uninterrupted access to course materials."&CHAR(10)&CHAR(10)&"If you have already made the payment, please disregard this message."&CHAR(10)&CHAR(10)&"Best regards,"&CHAR(10)&"Training Team",IF(E11="Paid","Dear "&B11&","&CHAR(10)&CHAR(10)&"Thank you for your payment! We are pleased to confirm that your fee for the "&D11&" course enrolled on "&TEXT(F11,"YYYY-MM-DD")&" has been successfully received."&CHAR(10)&CHAR(10)&"You now have full access to all course materials and resources."&CHAR(10)&CHAR(10)&"We wish you the best in your learning journey!"&CHAR(10)&CHAR(10)&"Best regards,"&CHAR(10)&"Training Team","")) -> Dear Karan Verma, This is a friendly reminder that your fee for the Advanced Excel course enrolled on 2026-01-11 is still pending. Please complete your payment at your earliest convenience to continue uninterrupted access to course materials. If you have already made the payment, please disregard this message. Best regards, Training Team | I11: =IF(D11="Advanced Excel","Dear "&B11&", We hope you're enjoying your Advanced Excel course that you enrolled in on "&TEXT(F11,"YYYY-MM-DD")&_xlfn._LONGTEXT(". We wanted to check in on your progress and see if you have any questions about the course material. Our team is here to support your learning journey! Here are some resources you might find helpful: • Access our Excel formula library • Join our weekly"," live Q&A sessions • Download practice worksheets Feel free to reach out if you need any assistance. Best regards, Training Team"),"") -> Dear Karan Verma, We hope you're enjoying your Advanced Excel course that you enrolled in on 2026-01-11. We wanted to check in on your progress and see if you have any questions about the course material. Our team is here to support your learning journey! Here are some resources you might find helpful: • Access our Excel formula library • Join our weekly live Q&A sessions • Download practice worksheets Feel free to reach out if you need any assistance. Best regards, Training Team
A12: 111 | B12: Priya Gupta | C12: user11@email.com | D12: Power BI | E12: Paid | F12: 46034 | G12: =IF(E12="Pending","Payment Reminder - "&D12&" Course Fee Due",IF(E12="Paid","Payment Confirmation - "&D12&" Course Fee Received","")) -> Payment Confirmation - Power BI Course Fee Received | H12: =IF(E12="Pending","Dear "&B12&","&CHAR(10)&CHAR(10)&"This is a friendly reminder that your fee for the "&D12&" course enrolled on "&TEXT(F12,"YYYY-MM-DD")&" is still pending."&CHAR(10)&CHAR(10)&"Please complete your payment at your earliest convenience to continue uninterrupted access to course materials."&CHAR(10)&CHAR(10)&"If you have already made the payment, please disregard this message."&CHAR(10)&CHAR(10)&"Best regards,"&CHAR(10)&"Training Team",IF(E12="Paid","Dear "&B12&","&CHAR(10)&CHAR(10)&"Thank you for your payment! We are pleased to confirm that your fee for the "&D12&" course enrolled on "&TEXT(F12,"YYYY-MM-DD")&" has been successfully received."&CHAR(10)&CHAR(10)&"You now have full access to all course materials and resources."&CHAR(10)&CHAR(10)&"We wish you the best in your learning journey!"&CHAR(10)&CHAR(10)&"Best regards,"&CHAR(10)&"Training Team","")) -> Dear Priya Gupta, Thank you for your payment! We are pleased to confirm that your fee for the Power BI course enrolled on 2026-01-12 has been successfully received. You now have full access to all course materials and resources. We wish you the best in your learning journey! Best regards, Training Team | I12: =IF(D12="Advanced Excel","Dear "&B12&", We hope you're enjoying your Advanced Excel course that you enrolled in on "&TEXT(F12,"YYYY-MM-DD")&_xlfn._LONGTEXT(". We wanted to check in on your progress and see if you have any questions about the course material. Our team is here to support your learning journey! Here are some resources you might find helpful: • Access our Excel formula library • Join our weekly"," live Q&A sessions • Download practice worksheets Feel free to reach out if you need any assistance. Best regards, Training Team"),"")
A13: 112 | B13: Aman Singh | C13: user12@email.com | D13: GST Mastery | E13: Paid | F13: 46035 | G13: =IF(E13="Pending","Payment Reminder - "&D13&" Course Fee Due",IF(E13="Paid","Payment Confirmation - "&D13&" Course Fee Received","")) -> Payment Confirmation - GST Mastery Course Fee Received | H13: =IF(E13="Pending","Dear "&B13&","&CHAR(10)&CHAR(10)&"This is a friendly reminder that your fee for the "&D13&" course enrolled on "&TEXT(F13,"YYYY-MM-DD")&" is still pending."&CHAR(10)&CHAR(10)&"Please complete your payment at your earliest convenience to continue uninterrupted access to course materials."&CHAR(10)&CHAR(10)&"If you have already made the payment, please disregard this message."&CHAR(10)&CHAR(10)&"Best regards,"&CHAR(10)&"Training Team",IF(E13="Paid","Dear "&B13&","&CHAR(10)&CHAR(10)&"Thank you for your payment! We are pleased to confirm that your fee for the "&D13&" course enrolled on "&TEXT(F13,"YYYY-MM-DD")&" has been successfully received."&CHAR(10)&CHAR(10)&"You now have full access to all course materials and resources."&CHAR(10)&CHAR(10)&"We wish you the best in your learning journey!"&CHAR(10)&CHAR(10)&"Best regards,"&CHAR(10)&"Training Team","")) -> Dear Aman Singh, Thank you for your payment! We are pleased to confirm that your fee for the GST Mastery course enrolled on 2026-01-13 has been successfully received. You now have full access to all course materials and resources. We wish you the best in your learning journey! Best regards, Training Team | I13: =IF(D13="Advanced Excel","Dear "&B13&", We hope you're enjoying your Advanced Excel course that you enrolled in on "&TEXT(F13,"YYYY-MM-DD")&_xlfn._LONGTEXT(". We wanted to check in on your progress and see if you have any questions about the course material. Our team is here to support your learning journey! Here are some resources you might find helpful: • Access our Excel formula library • Join our weekly"," live Q&A sessions • Download practice worksheets Feel free to reach out if you need any assistance. Best regards, Training Team"),"")
... A41: 140 | B41: Simran Singh | C41: user40@email.com | D41: Advanced Excel | E41: Paid | F41: 46063 | G41: =IF(E41="Pending","Payment Reminder - "&D41&" Course Fee Due",IF(E41="Paid","Payment Confirmation - "&D41&" Course Fee Received","")) -> Payment Confirmation - Advanced Excel Course Fee Received | H41: =IF(E41="Pending","Dear "&B41&","&CHAR(10)&CHAR(10)&"This is a friendly reminder that your fee for the "&D41&" course enrolled on "&TEXT(F41,"YYYY-MM-DD")&" is still pending."&CHAR(10)&CHAR(10)&"Please complete your payment at your earliest convenience to continue uninterrupted access to course materials."&CHAR(10)&CHAR(10)&"If you have already made the payment, please disregard this message."&CHAR(10)&CHAR(10)&"Best regards,"&CHAR(10)&"Training Team",IF(E41="Paid","Dear "&B41&","&CHAR(10)&CHAR(10)&"Thank you for your payment! We are pleased to confirm that your fee for the "&D41&" course enrolled on "&TEXT(F41,"YYYY-MM-DD")&" has been successfully received."&CHAR(10)&CHAR(10)&"You now have full access to all course materials and resources."&CHAR(10)&CHAR(10)&"We wish you the best in your learning journey!"&CHAR(10)&CHAR(10)&"Best regards,"&CHAR(10)&"Training Team","")) -> Dear Simran Singh, Thank you for your payment! We are pleased to confirm that your fee for the Advanced Excel course enrolled on 2026-02-10 has been successfully received. You now have full access to all course materials and resources. We wish you the best in your learning journey! Best regards, Training Team | I41: =IF(D41="Advanced Excel","Dear "&B41&", We hope you're enjoying your Advanced Excel course that you enrolled in on "&TEXT(F41,"YYYY-MM-DD")&_xlfn._LONGTEXT(". We wanted to check in on your progress and see if you have any questions about the course material. Our team is here to support your learning journey! Here are some resources you might find helpful: • Access our Excel formula library • Join our weekly"," live Q&A sessions • Download practice worksheets Feel free to reach out if you need any assistance. Best regards, Training Team"),"") -> Dear Simran Singh, We hope you're enjoying your Advanced Excel course that you enrolled in on 2026-02-10. We wanted to check in on your progress and see if you have any questions about the course material. Our team is here to support your learning journey! Here are some resources you might find helpful: • Access our Excel formula library • Join our weekly live Q&A sessions • Download practice worksheets Feel free to reach out if you need any assistance. Best regards, Training Team

Sheet Raw_Messy_Data
A1: Name | B1: City | C1: Sales
A2: Priya | B2: Mumbai | C2: 7801
A3: Rohit | B3: Delhi | C3: 19278
A4: Neha | B4: Bangalore | C4: 11295
A5: Aman | B5: Mumbai | C5: 19200
A6: Rohit | B6: Delhi | C6: 8411
A7: Priya | B7: Mumbai | C7: 13574
A8: Neha | B8: Pune | C8: 7700
A9: Rohit | B9: Mumbai | C9: 12815
A10: Priya | B10: Delhi | C10: 5871
A11: Rohit | B11: Mumbai | C11: 7169
A12: Rohit | B12: Delhi | C12: 5626
A13: Rohit | B13: Pune | C13: 12058
... A41: Rohit | B41: Pune | C41: 11859
A43: 📊 Data Cleaning Summary
A44: Original Records: | B44: 44
A45: Cleaned Records: | B45: 40
A46: Duplicates Removed: | B46: 4
A47: Unique Names: | B47: 4
A48: Unique Cities: | B48: 4
A50: Standardized Cities:
A51: Bangalore, Delhi, Mumbai, Pune

Sheet Payroll_Data
A1: Emp_ID | B1: Employee_Name | C1: Department | D1: Basic_Salary | E1: Bonus | F1: Deductions | G1: Net_Salary
A2: 201 | B2: Anita Singh | C2: IT | D2: 45902 | E2: 5986 | F2: 2200 | G2: =D2+E2-F2 -> 49688
A3: 202 | B3: Rahul Singh | C3: Sales | D3: 53315 | E3: 2868 | F3: 1636 | G3: =D3+E3-F3 -> 54547
A4: 203 | B4: Rohit Singh | C4: Accounts | D4: 40336 | E4: 5556 | F4: 2065 | G4: =D4+E4-F4 -> 43827
A5: 204 | B5: Arjun Verma | C5: HR | D5: 48066 | E5: 2538 | F5: 2166 | G5: =D5+E5-F5 -> 48438
A6: 205 | B6: Priya Singh | C6: Accounts | D6: 57772 | E6: 2192 | F6: 768 | G6: =D6+E6-F6 -> 59196
A7: 206 | B7: Anita Verma | C7: IT | D7: 47690 | E7: 6945 | F7: 1912 | G7: =D7+E7-F7 -> 52723
A8: 207 | B8: Priya Verma | C8: Admin | D8: 44668 | E8: 7649 | F8: 2734 | G8: =D8+E8-F8 -> 49583
A9: 208 | B9: Arjun Kumar | C9: HR | D9: 41888 | E9: 4455 | F9: 1771 | G9: =D9+E9-F9 -> 44572
A10: 209 | B10: Karan Singh | C10: Accounts | D10: 43908 | E10: 6913 | F10: 2077 | G10: =D10+E10-F10 -> 48744
A11: 210 | B11: Nikhil Verma | C11: HR | D11: 36734 | E11: 4610 | F11: 2769 | G11: =D11+E11-F11 -> 38575
A12: 211 | B12: Nikhil Singh | C12: IT | D12: 38287 | E12: 3133 | F12: 2437 | G12: =D12+E12-F12 -> 38983
A13: 212 | B13: Neha Singh | C13: Accounts | D13: 39777 | E13: 7294 | F13: 2153 | G13: =D13+E13-F13 -> 44918
... A41: 240 | B41: Arjun Singh | C41: Admin | D41: 47808 | E41: 4561 | F41: 2892 | G41: =D41+E41-F41 -> 49477

Sheet Payroll_Summary
A1: 📊 Department-Wise Payroll Summary
A3: Department | B3: Employee_Count | C3: Total_Basic_Salary | D3: Total_Bonus | E3: Total_Deductions | F3: Total_Net_Salary | G3: Avg_Net_Salary
A4: Accounts | B4: =COUNTIF(Payroll_Data!C:C,"Accounts") -> 5 | C4: =SUMIF(Payroll_Data!C:C,"Accounts",Payroll_Data!D:D) -> 224259 | D4: =SUMIF(Payroll_Data!C:C,"Accounts",Payroll_Data!E:E) -> 27697 | E4: =SUMIF(Payroll_Data!C:C,"Accounts",Payroll_Data!F:F) -> 7571 | F4: =SUMIF(Payroll_Data!C:C,"Accounts",Payroll_Data!G:G) -> 244385 | G4: =AVERAGEIF(Payroll_Data!C:C,"Accounts",Payroll_Data!G:G) -> 48877
A5: Admin | B5: =COUNTIF(Payroll_Data!C:C,"Admin") -> 6 | C5: =SUMIF(Payroll_Data!C:C,"Admin",Payroll_Data!D:D) -> 275278 | D5: =SUMIF(Payroll_Data!C:C,"Admin",Payroll_Data!E:E) -> 28200 | E5: =SUMIF(Payroll_Data!C:C,"Admin",Payroll_Data!F:F) -> 10706 | F5: =SUMIF(Payroll_Data!C:C,"Admin",Payroll_Data!G:G) -> 292772 | G5: =AVERAGEIF(Payroll_Data!C:C,"Admin",Payroll_Data!G:G) -> 48795.333
A6: HR | B6: =COUNTIF(Payroll_Data!C:C,"HR") -> 8 | C6: =SUMIF(Payroll_Data!C:C,"HR",Payroll_Data!D:D) -> 380929 | D6: =SUMIF(Payroll_Data!C:C,"HR",Payroll_Data!E:E) -> 35706 | E6: =SUMIF(Payroll_Data!C:C,"HR",Payroll_Data!F:F) -> 14754 | F6: =SUMIF(Payroll_Data!C:C,"HR",Payroll_Data!G:G) -> 401881 | G6: =AVERAGEIF(Payroll_Data!C:C,"HR",Payroll_Data!G:G) -> 50235.125
A7: IT | B7: =COUNTIF(Payroll_Data!C:C,"IT") -> 4 | C7: =SUMIF(Payroll_Data!C:C,"IT",Payroll_Data!D:D) -> 165885 | D7: =SUMIF(Payroll_Data!C:C,"IT",Payroll_Data!E:E) -> 19403 | E7: =SUMIF(Payroll_Data!C:C,"IT",Payroll_Data!F:F) -> 7524 | F7: =SUMIF(Payroll_Data!C:C,"IT",Payroll_Data!G:G) -> 177764 | G7: =AVERAGEIF(Payroll_Data!C:C,"IT",Payroll_Data!G:G) -> 44441
A8: Marketing | B8: =COUNTIF(Payroll_Data!C:C,"Marketing") -> 7 | C8: =SUMIF(Payroll_Data!C:C,"Marketing",Payroll_Data!D:D) -> 324483 | D8: =SUMIF(Payroll_Data!C:C,"Marketing",Payroll_Data!E:E) -> 32658 | E8: =SUMIF(Payroll_Data!C:C,"Marketing",Payroll_Data!F:F) -> 11507 | F8: =SUMIF(Payroll_Data!C:C,"Marketing",Payroll_Data!G:G) -> 345634 | G8: =AVERAGEIF(Payroll_Data!C:C,"Marketing",Payroll_Data!G:G) -> 49376.286
A9: Sales | B9: =COUNTIF(Payroll_Data!C:C,"Sales") -> 10 | C9: =SUMIF(Payroll_Data!C:C,"Sales",Payroll_Data!D:D) -> 493427 | D9: =SUMIF(Payroll_Data!C:C,"Sales",Payroll_Data!E:E) -> 43734 | E9: =SUMIF(Payroll_Data!C:C,"Sales",Payroll_Data!F:F) -> 16571 | F9: =SUMIF(Payroll_Data!C:C,"Sales",Payroll_Data!G:G) -> 520590 | G9: =AVERAGEIF(Payroll_Data!C:C,"Sales",Payroll_Data!G:G) -> 52059
A10: GRAND TOTAL | B10: =SUM(B4:B9) -> 40 | C10: =SUM(C4:C9) -> 1864261 | D10: =SUM(D4:D9) -> 187398 | E10: =SUM(E4:E9) -> 68633 | F10: =SUM(F4:F9) -> 1983026 | G10: =AVERAGE(G4:G9) -> 48963.957
A12: 📌 Conditional Formatting Applied:
A13: • Employee Count: Blue data bars show relative department size
A14: • Total Net Salary: Color scale (Red=Low, Yellow=Mid, Green=High)
A15: • Avg Net Salary: Arrow icons (↑ High, → Mid, ↓ Low)

Sheet Bank_Books
A1: Date | B1: Description | C1: Amount
A2: 46023 | B2: Consulting Fee | C2: 21673
A3: 46024 | B3: Consulting Fee | C3: -13047
A4: 46025 | B4: Consulting Fee | C4: 19375
A5: 46026 | B5: Utility Bill | C5: 12429
A6: 46027 | B6: Office Rent | C6: 9070
A7: 46028 | B7: Software Purchase | C7: 15876
A8: 46029 | B8: Client Payment | C8: -7221
A9: 46030 | B9: Client Payment | C9: -2163
A10: 46031 | B10: Utility Bill | C10: -9499
A11: 46032 | B11: Utility Bill | C11: -14246
A12: 46033 | B12: Utility Bill | C12: 8049
A13: 46034 | B13: Office Rent | C13: 12737
... A41: 46062 | B41: Utility Bill | C41: 23021

Sheet Bank_Statement
A1: Date | B1: Description | C1: Amount
A2: 46023 | B2: Client Payment | C2: 10997
A3: 46024 | B3: Office Rent | C3: 19376
A4: 46025 | B4: Office Rent | C4: 18559
A5: 46026 | B5: Client Payment | C5: -7646
A6: 46027 | B6: Office Rent | C6: 2360
A7: 46028 | B7: Client Payment | C7: 17153
A8: 46029 | B8: Utility Bill | C8: -4586
A9: 46030 | B9: Office Rent | C9: -3633
A10: 46031 | B10: Bank Charges | C10: 12001
A11: 46032 | B11: Client Payment | C11: -8247
A12: 46033 | B12: Utility Bill | C12: -11811
A13: 46034 | B13: Client Payment | C13: 18674
... A41: 46062 | B41: Client Payment | C41: 3328

Sheet Bank_Reconciliation
A1: 🏦 Bank Reconciliation Report
A2: Comparison of Bank_Books vs Bank_Statement
A4: 📘 Bank Books (Internal Records) | G4: 📗 Bank Statement (External Records)
A5: Date | B5: Description | C5: Amount | D5: Match_Key | E5: Match_Status | F5: Date_Match | G5: Date | H5: Description | I5: Amount | J5: Match_Key | K5: Match_Status | L5: Date_Match
A6: =Bank_Books!A2 -> 46023 | B6: =Bank_Books!B2 -> Consulting Fee | C6: =Bank_Books!C2 -> 21673 | D6: =TEXT(A6,"YYYY-MM-DD")&"|"&B6&"|"&C6 -> 2026-01-01|Consulting Fee|21673 | E6: =IF(COUNTIF($J$6:$J$45,D6)>0,"✓ Matched","✗ Unmatched") -> ✗ Unmatched | F6: =IF(COUNTIF($G$6:$G$45,A6)>0,"Date exists in Statement","Date not found") -> Date exists in Statement | G6: =Bank_Statement!A2 -> 46023 | H6: =Bank_Statement!B2 -> Client Payment | I6: =Bank_Statement!C2 -> 10997 | J6: =TEXT(G6,"YYYY-MM-DD")&"|"&H6&"|"&I6 -> 2026-01-01|Client Payment|10997 | K6: =IF(COUNTIF($D$6:$D$45,J6)>0,"✓ Matched","✗ Unmatched") -> ✗ Unmatched | L6: =IF(COUNTIF($A$6:$A$45,G6)>0,"Date exists in Books","Date not found") -> Date exists in Books
A7: =Bank_Books!A3 -> 46024 | B7: =Bank_Books!B3 -> Consulting Fee | C7: =Bank_Books!C3 -> -13047 | D7: =TEXT(A7,"YYYY-MM-DD")&"|"&B7&"|"&C7 -> 2026-01-02|Consulting Fee|-13047 | E7: =IF(COUNTIF($J$6:$J$45,D7)>0,"✓ Matched","✗ Unmatched") -> ✗ Unmatched | F7: =IF(COUNTIF($G$6:$G$45,A7)>0,"Date exists in Statement","Date not found") -> Date exists in Statement | G7: =Bank_Statement!A3 -> 46024 | H7: =Bank_Statement!B3 -> Office Rent | I7: =Bank_Statement!C3 -> 19376 | J7: =TEXT(G7,"YYYY-MM-DD")&"|"&H7&"|"&I7 -> 2026-01-02|Office Rent|19376 | K7: =IF(COUNTIF($D$6:$D$45,J7)>0,"✓ Matched","✗ Unmatched") -> ✗ Unmatched | L7: =IF(COUNTIF($A$6:$A$45,G7)>0,"Date exists in Books","Date not found") -> Date exists in Books
A8: =Bank_Books!A4 -> 46025 | B8: =Bank_Books!B4 -> Consulting Fee | C8: =Bank_Books!C4 -> 19375 | D8: =TEXT(A8,"YYYY-MM-DD")&"|"&B8&"|"&C8 -> 2026-01-03|Consulting Fee|19375 | E8: =IF(COUNTIF($J$6:$J$45,D8)>0,"✓ Matched","✗ Unmatched") -> ✗ Unmatched | F8: =IF(COUNTIF($G$6:$G$45,A8)>0,"Date exists in Statement","Date not found") -> Date exists in Statement | G8: =Bank_Statement!A4 -> 46025 | H8: =Bank_Statement!B4 -> Office Rent | I8: =Bank_Statement!C4 -> 18559 | J8: =TEXT(G8,"YYYY-MM-DD")&"|"&H8&"|"&I8 -> 2026-01-03|Office Rent|18559 | K8: =IF(COUNTIF($D$6:$D$45,J8)>0,"✓ Matched","✗ Unmatched") -> ✗ Unmatched | L8: =IF(COUNTIF($A$6:$A$45,G8)>0,"Date exists in Books","Date not found") -> Date exists in Books
A9: =Bank_Books!A5 -> 46026 | B9: =Bank_Books!B5 -> Utility Bill | C9: =Bank_Books!C5 -> 12429 | D9: =TEXT(A9,"YYYY-MM-DD")&"|"&B9&"|"&C9 -> 2026-01-04|Utility Bill|12429 | E9: =IF(COUNTIF($J$6:$J$45,D9)>0,"✓ Matched","✗ Unmatched") -> ✗ Unmatched | F9: =IF(COUNTIF($G$6:$G$45,A9)>0,"Date exists in Statement","Date not found") -> Date exists in Statement | G9: =Bank_Statement!A5 -> 46026 | H9: =Bank_Statement!B5 -> Client Payment | I9: =Bank_Statement!C5 -> -7646 | J9: =TEXT(G9,"YYYY-MM-DD")&"|"&H9&"|"&I9 -> 2026-01-04|Client Payment|-7646 | K9: =IF(COUNTIF($D$6:$D$45,J9)>0,"✓ Matched","✗ Unmatched") -> ✗ Unmatched | L9: =IF(COUNTIF($A$6:$A$45,G9)>0,"Date exists in Books","Date not found") -> Date exists in Books
A10: =Bank_Books!A6 -> 46027 | B10: =Bank_Books!B6 -> Office Rent | C10: =Bank_Books!C6 -> 9070 | D10: =TEXT(A10,"YYYY-MM-DD")&"|"&B10&"|"&C10 -> 2026-01-05|Office Rent|9070 | E10: =IF(COUNTIF($J$6:$J$45,D10)>0,"✓ Matched","✗ Unmatched") -> ✗ Unmatched | F10: =IF(COUNTIF($G$6:$G$45,A10)>0,"Date exists in Statement","Date not found") -> Date exists in Statement | G10: =Bank_Statement!A6 -> 46027 | H10: =Bank_Statement!B6 -> Office Rent | I10: =Bank_Statement!C6 -> 2360 | J10: =TEXT(G10,"YYYY-MM-DD")&"|"&H10&"|"&I10 -> 2026-01-05|Office Rent|2360 | K10: =IF(COUNTIF($D$6:$D$45,J10)>0,"✓ Matched","✗ Unmatched") -> ✗ Unmatched | L10: =IF(COUNTIF($A$6:$A$45,G10)>0,"Date exists in Books","Date not found") -> Date exists in Books
A11: =Bank_Books!A7 -> 46028 | B11: =Bank_Books!B7 -> Software Purchase | C11: =Bank_Books!C7 -> 15876 | D11: =TEXT(A11,"YYYY-MM-DD")&"|"&B11&"|"&C11 -> 2026-01-06|Software Purchase|15876 | E11: =IF(COUNTIF($J$6:$J$45,D11)>0,"✓ Matched","✗ Unmatched") -> ✗ Unmatched | F11: =IF(COUNTIF($G$6:$G$45,A11)>0,"Date exists in Statement","Date not found") -> Date exists in Statement | G11: =Bank_Statement!A7 -> 46028 | H11: =Bank_Statement!B7 -> Client Payment | I11: =Bank_Statement!C7 -> 17153 | J11: =TEXT(G11,"YYYY-MM-DD")&"|"&H11&"|"&I11 -> 2026-01-06|Client Payment|17153 | K11: =IF(COUNTIF($D$6:$D$45,J11)>0,"✓ Matched","✗ Unmatched") -> ✗ Unmatched | L11: =IF(COUNTIF($A$6:$A$45,G11)>0,"Date exists in Books","Date not found") -> Date exists in Books
A12: =Bank_Books!A8 -> 46029 | B12: =Bank_Books!B8 -> Client Payment | C12: =Bank_Books!C8 -> -7221 | D12: =TEXT(A12,"YYYY-MM-DD")&"|"&B12&"|"&C12 -> 2026-01-07|Client Payment|-7221 | E12: =IF(COUNTIF($J$6:$J$45,D12)>0,"✓ Matched","✗ Unmatched") -> ✗ Unmatched | F12: =IF(COUNTIF($G$6:$G$45,A12)>0,"Date exists in Statement","Date not found") -> Date exists in Statement | G12: =Bank_Statement!A8 -> 46029 | H12: =Bank_Statement!B8 -> Utility Bill | I12: =Bank_Statement!C8 -> -4586 | J12: =TEXT(G12,"YYYY-MM-DD")&"|"&H12&"|"&I12 -> 2026-01-07|Utility Bill|-4586 | K12: =IF(COUNTIF($D$6:$D$45,J12)>0,"✓ Matched","✗ Unmatched") -> ✗ Unmatched | L12: =IF(COUNTIF($A$6:$A$45,G12)>0,"Date exists in Books","Date not found") -> Date exists in Books
A13: =Bank_Books!A9 -> 46030 | B13: =Bank_Books!B9 -> Client Payment | C13: =Bank_Books!C9 -> -2163 | D13: =TEXT(A13,"YYYY-MM-DD")&"|"&B13&"|"&C13 -> 2026-01-08|Client Payment|-2163 | E13: =IF(COUNTIF($J$6:$J$45,D13)>0,"✓ Matched","✗ Unmatched") -> ✗ Unmatched | F13: =IF(COUNTIF($G$6:$G$45,A13)>0,"Date exists in Statement","Date not found") -> Date exists in Statement | G13: =Bank_Statement!A9 -> 46030 | H13: =Bank_Statement!B9 -> Office Rent | I13: =Bank_Statement!C9 -> -3633 | J13: =TEXT(G13,"YYYY-MM-DD")&"|"&H13&"|"&I13 -> 2026-01-08|Office Rent|-3633 | K13: =IF(COUNTIF($D$6:$D$45,J13)>0,"✓ Matched","✗ Unmatched") -> ✗ Unmatched | L13: =IF(COUNTIF($A$6:$A$45,G13)>0,"Date exists in Books","Date not found") -> Date exists in Books
A14: =Bank_Books!A10 -> 46031 | B14: =Bank_Books!B10 -> Utility Bill | C14: =Bank_Books!C10 -> -9499 | D14: =TEXT(A14,"YYYY-MM-DD")&"|"&B14&"|"&C14 -> 2026-01-09|Utility Bill|-9499 | E14: =IF(COUNTIF($J$6:$J$45,D14)>0,"✓ Matched","✗ Unmatched") -> ✗ Unmatched | F14: =IF(COUNTIF($G$6:$G$45,A14)>0,"Date exists in Statement","Date not found") -> Date exists in Statement | G14: =Bank_Statement!A10 -> 46031 | H14: =Bank_Statement!B10 -> Bank Charges | I14: =Bank_Statement!C10 -> 12001 | J14: =TEXT(G14,"YYYY-MM-DD")&"|"&H14&"|"&I14 -> 2026-01-09|Bank Charges|12001 | K14: =IF(COUNTIF($D$6:$D$45,J14)>0,"✓ Matched","✗ Unmatched") -> ✗ Unmatched | L14: =IF(COUNTIF($A$6:$A$45,G14)>0,"Date exists in Books","Date not found") -> Date exists in Books
A15: =Bank_Books!A11 -> 46032 | B15: =Bank_Books!B11 -> Utility Bill | C15: =Bank_Books!C11 -> -14246 | D15: =TEXT(A15,"YYYY-MM-DD")&"|"&B15&"|"&C15 -> 2026-01-10|Utility Bill|-14246 | E15: =IF(COUNTIF($J$6:$J$45,D15)>0,"✓ Matched","✗ Unmatched") -> ✗ Unmatched | F15: =IF(COUNTIF($G$6:$G$45,A15)>0,"Date exists in Statement","Date not found") -> Date exists in Statement | G15: =Bank_Statement!A11 -> 46032 | H15: =Bank_Statement!B11 -> Client Payment | I15: =Bank_Statement!C11 -> -8247 | J15: =TEXT(G15,"YYYY-MM-DD")&"|"&H15&"|"&I15 -> 2026-01-10|Client Payment|-8247 | K15: =IF(COUNTIF($D$6:$D$45,J15)>0,"✓ Matched","✗ Unmatched") -> ✗ Unmatched | L15: =IF(COUNTIF($A$6:$A$45,G15)>0,"Date exists in Books","Date not found") -> Date exists in Books
A16: =Bank_Books!A12 -> 46033 | B16: =Bank_Books!B12 -> Utility Bill | C16: =Bank_Books!C12 -> 8049 | D16: =TEXT(A16,"YYYY-MM-DD")&"|"&B16&"|"&C16 -> 2026-01-11|Utility Bill|8049 | E16: =IF(COUNTIF($J$6:$J$45,D16)>0,"✓ Matched","✗ Unmatched") -> ✗ Unmatched | F16: =IF(COUNTIF($G$6:$G$45,A16)>0,"Date exists in Statement","Date not found") -> Date exists in Statement | G16: =Bank_Statement!A12 -> 46033 | H16: =Bank_Statement!B12 -> Utility Bill | I16: =Bank_Statement!C12 -> -11811 | J16: =TEXT(G16,"YYYY-MM-DD")&"|"&H16&"|"&I16 -> 2026-01-11|Utility Bill|-11811 | K16: =IF(COUNTIF($D$6:$D$45,J16)>0,"✓ Matched","✗ Unmatched") -> ✗ Unmatched | L16: =IF(COUNTIF($A$6:$A$45,G16)>0,"Date exists in Books","Date not found") -> Date exists in Books
A17: =Bank_Books!A13 -> 46034 | B17: =Bank_Books!B13 -> Office Rent | C17: =Bank_Books!C13 -> 12737 | D17: =TEXT(A17,"YYYY-MM-DD")&"|"&B17&"|"&C17 -> 2026-01-12|Office Rent|12737 | E17: =IF(COUNTIF($J$6:$J$45,D17)>0,"✓ Matched","✗ Unmatched") -> ✗ Unmatched | F17: =IF(COUNTIF($G$6:$G$45,A17)>0,"Date exists in Statement","Date not found") -> Date exists in Statement | G17: =Bank_Statement!A13 -> 46034 | H17: =Bank_Statement!B13 -> Client Payment | I17: =Bank_Statement!C13 -> 18674 | J17: =TEXT(G17,"YYYY-MM-DD")&"|"&H17&"|"&I17 -> 2026-01-12|Client Payment|18674 | K17: =IF(COUNTIF($D$6:$D$45,J17)>0,"✓ Matched","✗ Unmatched") -> ✗ Unmatched | L17: =IF(COUNTIF($A$6:$A$45,G17)>0,"Date exists in Books","Date not found") -> Date exists in Books
... A45: =Bank_Books!A41 -> 46062 | B45: =Bank_Books!B41 -> Utility Bill | C45: =Bank_Books!C41 -> 23021 | D45: =TEXT(A45,"YYYY-MM-DD")&"|"&B45&"|"&C45 -> 2026-02-09|Utility Bill|23021 | E45: =IF(COUNTIF($J$6:$J$45,D45)>0,"✓ Matched","✗ Unmatched") -> ✗ Unmatched | F45: =IF(COUNTIF($G$6:$G$45,A45)>0,"Date exists in Statement","Date not found") -> Date exists in Statement | G45: =Bank_Statement!A41 -> 46062 | H45: =Bank_Statement!B41 -> Client Payment | I45: =Bank_Statement!C41 -> 3328 | J45: =TEXT(G45,"YYYY-MM-DD")&"|"&H45&"|"&I45 -> 2026-02-09|Client Payment|3328 | K45: =IF(COUNTIF($D$6:$D$45,J45)>0,"✓ Matched","✗ Unmatched") -> ✗ Unmatched | L45: =IF(COUNTIF($A$6:$A$45,G45)>0,"Date exists in Books","Date not found") -> Date exists in Books
A48: 📊 Reconciliation Summary
A50: Metric | B50: Value | D50: 📋 Reconciliation Analysis
A51: Total Bank Books Entries | B51: =COUNTA(A6:A45) -> 40
A52: Total Bank Statement Entries | B52: =COUNTA(G6:G45) -> 40 | D52: The Bank Books and Bank Statement contain:
A53: Matched in Bank Books | B53: =COUNTIF(E6:E45,"✓ Matched") -> 0 | D53: • Same date range (Jan 1 - Feb 9, 2026)
A54: Unmatched in Bank Books | B54: =COUNTIF(E6:E45,"✗ Unmatched") -> 40 | D54: • Different transaction descriptions
A55: Matched in Bank Statement | B55: =COUNTIF(K6:K45,"✓ Matched") -> 0 | D55: • Different transaction amounts
A56: Unmatched in Bank Statement | B56: =COUNTIF(K6:K45,"✗ Unmatched") -> 40 | D56: • This indicates two independent record sources
A57: Bank Books Total Amount | B57: =SUM(C6:C45) -> 184616 | D57: • Full reconciliation requires manual review
A58: Bank Statement Total Amount | B58: =SUM(I6:I45) -> 209914
A59: Variance (Books - Statement) | B59: =B57-B58 -> -25298
A60: ⚠️ Unmatched Transactions Details
A62: Note: Transactions are matched based on Date + Description + Amount combination. Unmatched entries may indicate:
A63: • Transactions recorded in one book but not the other
A64: • Timing differences between internal records and bank processing
A65: • Data entry errors or discrepancies in amounts
A66: • Bank charges or fees not recorded in internal books
A69: 📅 Date-wise Amount Comparison
A71: Date | B71: Books Amount | C71: Statement Amount | D71: Difference
A72: =A6 -> 46023 | B72: =C6 -> 21673 | C72: =SUMIF($G$6:$G$45,A72,$I$6:$I$45) -> 10997 | D72: =B72-C72 -> 10676
A73: =A7 -> 46024 | B73: =C7 -> -13047 | C73: =SUMIF($G$6:$G$45,A73,$I$6:$I$45) -> 19376 | D73: =B73-C73 -> -32423
A74: =A8 -> 46025 | B74: =C8 -> 19375 | C74: =SUMIF($G$6:$G$45,A74,$I$6:$I$45) -> 18559 | D74: =B74-C74 -> 816
A75: =A9 -> 46026 | B75: =C9 -> 12429 | C75: =SUMIF($G$6:$G$45,A75,$I$6:$I$45) -> -7646 | D75: =B75-C75 -> 20075
...

Sheet Missing_Entries_Report
A1: 📋 Bank Reconciliation - Missing Entries Report
A2: Generated: 29/3/2026
A4: 📘 Missing from Bank Statement (Recorded in Books but NOT in Statement) | G4: 📗 Missing from Bank Books (Recorded in Statement but NOT in Books)
A5: Date | B5: Description | C5: Amount | D5: Match_Key | E5: Status | G5: Date | H5: Description | I5: Amount | J5: Match_Key | K5: Status
A6: 46023 | B6: Consulting Fee | C6: 21673 | D6: =TEXT(A6,"YYYY-MM-DD")&"|"&B6&"|"&C6 -> 2026-01-01|Consulting Fee|21673 | E6: =IF(COUNTIFS(Bank_Statement!A:A,A6,Bank_Statement!B:B,B6,Bank_Statement!C:C,C6)>0,"✓ Found","✗ Missing") -> ✗ Missing | G6: 46023 | H6: Client Payment | I6: 10997 | J6: =TEXT(G6,"YYYY-MM-DD")&"|"&H6&"|"&I6 -> 2026-01-01|Client Payment|10997 | K6: =IF(COUNTIFS(Bank_Books!A:A,G6,Bank_Books!B:B,H6,Bank_Books!C:C,I6)>0,"✓ Found","✗ Missing") -> ✗ Missing
A7: 46024 | B7: Consulting Fee | C7: -13047 | D7: =TEXT(A7,"YYYY-MM-DD")&"|"&B7&"|"&C7 -> 2026-01-02|Consulting Fee|-13047 | E7: =IF(COUNTIFS(Bank_Statement!A:A,A7,Bank_Statement!B:B,B7,Bank_Statement!C:C,C7)>0,"✓ Found","✗ Missing") -> ✗ Missing | G7: 46024 | H7: Office Rent | I7: 19376 | J7: =TEXT(G7,"YYYY-MM-DD")&"|"&H7&"|"&I7 -> 2026-01-02|Office Rent|19376 | K7: =IF(COUNTIFS(Bank_Books!A:A,G7,Bank_Books!B:B,H7,Bank_Books!C:C,I7)>0,"✓ Found","✗ Missing") -> ✗ Missing
A8: 46025 | B8: Consulting Fee | C8: 19375 | D8: =TEXT(A8,"YYYY-MM-DD")&"|"&B8&"|"&C8 -> 2026-01-03|Consulting Fee|19375 | E8: =IF(COUNTIFS(Bank_Statement!A:A,A8,Bank_Statement!B:B,B8,Bank_Statement!C:C,C8)>0,"✓ Found","✗ Missing") -> ✗ Missing | G8: 46025 | H8: Office Rent | I8: 18559 | J8: =TEXT(G8,"YYYY-MM-DD")&"|"&H8&"|"&I8 -> 2026-01-03|Office Rent|18559 | K8: =IF(COUNTIFS(Bank_Books!A:A,G8,Bank_Books!B:B,H8,Bank_Books!C:C,I8)>0,"✓ Found","✗ Missing") -> ✗ Missing
A9: 46026 | B9: Utility Bill | C9: 12429 | D9: =TEXT(A9,"YYYY-MM-DD")&"|"&B9&"|"&C9 -> 2026-01-04|Utility Bill|12429 | E9: =IF(COUNTIFS(Bank_Statement!A:A,A9,Bank_Statement!B:B,B9,Bank_Statement!C:C,C9)>0,"✓ Found","✗ Missing") -> ✗ Missing | G9: 46026 | H9: Client Payment | I9: -7646 | J9: =TEXT(G9,"YYYY-MM-DD")&"|"&H9&"|"&I9 -> 2026-01-04|Client Payment|-7646 | K9: =IF(COUNTIFS(Bank_Books!A:A,G9,Bank_Books!B:B,H9,Bank_Books!C:C,I9)>0,"✓ Found","✗ Missing") -> ✗ Missing
A10: 46027 | B10: Office Rent | C10: 9070 | D10: =TEXT(A10,"YYYY-MM-DD")&"|"&B10&"|"&C10 -> 2026-01-05|Office Rent|9070 | E10: =IF(COUNTIFS(Bank_Statement!A:A,A10,Bank_Statement!B:B,B10,Bank_Statement!C:C,C10)>0,"✓ Found","✗ Missing") -> ✗ Missing | G10: 46027 | H10: Office Rent | I10: 2360 | J10: =TEXT(G10,"YYYY-MM-DD")&"|"&H10&"|"&I10 -> 2026-01-05|Office Rent|2360 | K10: =IF(COUNTIFS(Bank_Books!A:A,G10,Bank_Books!B:B,H10,Bank_Books!C:C,I10)>0,"✓ Found","✗ Missing") -> ✗ Missing
